<?xml version='1.0'?>

<robot name="my_robot" xmlns:xacro="http://www.ros.org/wiki/xacro">

<xacro:include filename="$(find my_robot)/urdf/my_robot.gazebo" />

  <!--Links-->

  <link name="robot_footprint"></link>

  <link name='chassis'>
    <pose>0 0 0.1 0 0 0</pose>

    <inertial>
      <mass value="15.0"/>
      <origin xyz="0.0 0 0" rpy=" 0 0 0"/>
      <inertia
          ixx="0.1" ixy="0" ixz="0"
          iyy="0.1" iyz="0"
          izz="0.1"
      />
    </inertial>

    <collision name='chassis_collision'>
      <origin xyz="0 0 0" rpy=" 0 0 0"/> 
      <geometry>
        <box size=".4 .3 .1"/>
      </geometry>
    </collision>

    <visual name='chassis_visual'>
      <origin xyz="0 0 0" rpy=" 0 0 0"/>
      <geometry>
        <box size=".4 .3 .1"/>
      </geometry>
    </visual>

    <collision name='back_caster_collision'>
      <origin xyz="-0.15 0 -0.05" rpy=" 0 0 0"/>
      <geometry>
        <sphere radius="0.0499"/>
      </geometry>
    </collision>

    <visual name='back_caster_visual'>
      <origin xyz="-0.15 0 -0.05" rpy=" 0 0 0"/>
      <geometry>
        <sphere radius="0.05"/>
      </geometry>
    </visual>

    <collision name='front_caster_collision'>
      <origin xyz="0.15 0 -0.05" rpy=" 0 0 0"/>
      <geometry>
        <sphere radius="0.0499"/>
      </geometry>
    </collision>

    <visual name='front_caster_visual'>
      <origin xyz="0.15 0 -0.05" rpy=" 0 0 0"/>
      <geometry>
        <sphere radius="0.05"/>
      </geometry>
    </visual>

    <!--Upper part of the body-->
    <collision name='body_collision'>
      <origin xyz="0 0 0.15" rpy=" 0 0 0"/> 
      <geometry>
        <cylinder radius="0.14" length="0.2"/>
      </geometry>
    </collision>

    <visual name='body_visual'>
      <origin xyz="0 0 0.15" rpy=" 0 0 0"/>
      <geometry>
        <cylinder radius="0.14" length="0.2"/>
      </geometry>
    </visual>

    <collision name='arm_rigth_collision'>
      <origin xyz="0 -0.16 0.2" rpy=" 0 0 0"/>
      <geometry>
        <sphere radius="0.025"/>
      </geometry>
    </collision>

    <visual name='arm_rigth_visual'>
      <origin xyz="0 -0.16 0.2" rpy=" 0 0 0"/>
      <geometry>
        <sphere radius="0.025"/>
      </geometry>
    </visual>

    <collision name='arm_R_collision'>
      <origin xyz="0.03 -0.16 0.165" rpy=" 0 -0.6981 0"/> 
      <geometry>
        <cylinder radius="0.025" length="0.1"/>
      </geometry>
    </collision>

    <visual name='arm_R_visual'>
      <origin xyz="0.03 -0.16 0.165" rpy=" 0 -0.6981 0"/>
      <geometry>
        <cylinder radius="0.025" length="0.1"/>
      </geometry>
    </visual>

    <collision name='arm_left_collision'>
      <origin xyz="0 0.16 0.2" rpy=" 0 0 0"/>
      <geometry>
        <sphere radius="0.025"/>
      </geometry>
    </collision>

    <visual name='arm_left_visual'>
      <origin xyz="0 0.16 0.2" rpy=" 0 0 0"/>
      <geometry>
        <sphere radius="0.025"/>
      </geometry>
    </visual>

    <collision name='arm_L_collision'>
      <origin xyz="0.03 0.16 0.165" rpy=" 0 -0.6981 0"/> 
      <geometry>
        <cylinder radius="0.025" length="0.1"/>
      </geometry>
    </collision>

    <visual name='arm_L_visual'>
      <origin xyz="0.03 0.16 0.165" rpy=" 0 -0.6981 0"/>
      <geometry>
        <cylinder radius="0.025" length="0.1"/>
      </geometry>
    </visual>

    <collision name='neck_collision'>
      <origin xyz="-0.03 0 0.3" rpy=" 0 0 0"/> 
      <geometry>
        <cylinder radius="0.03" length="0.1"/>
      </geometry>
    </collision>

    <visual name='neck_visual'>
      <origin xyz="-0.03 0 0.3" rpy=" 0 0 0"/>
      <geometry>
        <cylinder radius="0.03" length="0.1"/>
      </geometry>
    </visual>

    <collision name='head_collision'>
      <origin xyz="0 0 0.38" rpy=" 0 0.4363 0"/> 
      <geometry>
        <cylinder radius="0.14" length="0.1"/>
      </geometry>
    </collision>

    <visual name='head_visual'>
      <origin xyz="0 0 0.38" rpy=" 0 0.4363 0"/>
      <geometry>
        <cylinder radius="0.14" length="0.1"/>
      </geometry>
    </visual>

  </link> 

  <!--Links wheels-->

  <link name="left_wheel">

    <inertial>
      <mass value="5.0"/>
      <origin xyz="0.0 0 0" rpy=" 0 1.5707 1.5707"/>
      <inertia
          ixx="0.1" ixy="0" ixz="0"
          iyy="0.1" iyz="0"
          izz="0.1"
      />
    </inertial>

    <collision name='left_wheel_collision'>
      <origin xyz="0 0 0" rpy=" 0 1.5707 1.5707"/> 
      <geometry>
        <cylinder radius="0.1" length="0.05"/>
      </geometry>
    </collision>

    <visual name='left_wheel_visual'>
      <origin xyz="0 0 0" rpy=" 0 1.5707 1.5707"/>
      <geometry>
        <cylinder radius="0.1" length="0.05"/>
      </geometry>
    </visual>
  </link>

  <link name="right_wheel">

    <inertial>
      <mass value="5.0"/>
      <origin xyz="0.0 0 0" rpy=" 0 1.5707 1.5707"/>
      <inertia
          ixx="0.1" ixy="0" ixz="0"
          iyy="0.1" iyz="0"
          izz="0.1"
      />
    </inertial>

    <collision name='right_wheel_collision'>
      <origin xyz="0 0 0" rpy=" 0 1.5707 1.5707"/> 
      <geometry>
        <cylinder radius="0.1" length="0.05"/>
      </geometry>
    </collision>

    <visual name='right_wheel_visual'>
      <origin xyz="0 0 0" rpy=" 0 1.5707 1.5707"/>
      <geometry>
        <cylinder radius="0.1" length="0.05"/>
      </geometry>
    </visual>
  </link>


  <!--Link camera-->

  <link name="camera">

    <inertial>
      <mass value="0.1"/>
      <origin xyz="0.0 0 0" rpy=" 0 0 0"/>
      <inertia
          ixx="1e-6" ixy="0" ixz="0"
          iyy="1e-6" iyz="0"
          izz="1e-6"
      />
    </inertial>

    <box_inertia m="0.1" x="0.05" y="0.05" z="0.05" />

    <collision name='camera_collision'>
      <origin xyz="0 0 0" rpy=" 0 0 0"/> 
      <geometry>
        <box size="0.05 0.05 0.05"/>
      </geometry>
    </collision>

    <visual name='camera_visual'>
      <origin xyz="0 0 0" rpy=" 0 0 0"/>
      <geometry>
        <box size="0.05 0.05 0.05"/>
      </geometry>
    </visual>
  </link>

  <!--Link camera optical-->

  <link name="camera_link_optical">
  </link>

  <!--Link hokuyo-->

  <link name="hokuyo">

    <inertial>
      <mass value="1e-5"/>
      <origin xyz="0.0 0 0" rpy=" 0 0 0"/>
      <inertia
          ixx="1e-6" ixy="0" ixz="0"
          iyy="1e-6" iyz="0"
          izz="1e-6"
      />
    </inertial>

    <collision name='hokuyo_collision'>
      <origin xyz="0 0 0" rpy=" 0 0 0"/> 
      <geometry>
        <box size="0.1 0.1 0.1"/>
      </geometry>
    </collision>

    <visual name='hokuyo_visual'>
      <origin xyz="0 0 0" rpy=" 0 0 0"/>
      <geometry>
        <mesh filename= "package://my_robot/meshes/hokuyo.dae"/>
      </geometry>
    </visual>
  </link>

  <!--Joints-->

  <joint name="robot_footprint_joint" type="fixed">
    <origin xyz="0 0 0" rpy="0 0 0" />
    <parent link="robot_footprint"/>
    <child link="chassis" />
  </joint>

  <!--Joints Wheels-->

  <joint type="continuous" name="left_wheel_hinge">
    <origin xyz="0 0.18 0" rpy="0 0 0"/>
    <child link="left_wheel"/>
    <parent link="chassis"/>
    <axis xyz="0 1 0" rpy="0 0 0"/>
    <limit effort="10000" velocity="1000"/>
    <dynamics damping="1.0" friction="1.0"/>
  </joint>

  <joint type="continuous" name="right_wheel_hinge">
    <origin xyz="0 -0.18 0" rpy="0 0 0"/>
    <child link="right_wheel"/>
    <parent link="chassis"/>
    <axis xyz="0 1 0" rpy="0 0 0"/>
    <limit effort="10000" velocity="1000"/>
    <dynamics damping="1.0" friction="1.0"/>
  </joint>

  <!--Joint Camera-->

  <joint type="fixed" name="camera_joint">
    <origin xyz="0.2 0 0" rpy="0 0 0"/>
    <child link="camera"/>
    <parent link="chassis"/>
    <axis xyz="0 1 0" rpy="0 0 0"/>
  </joint>

  <!--Joint Camera Optical-->

  <joint name="camera_optical_joint" type="fixed">
    <origin xyz="0 0 0" rpy="-1.5707 0 -1.5707"/>
    <parent link="camera"/>
    <child link="camera_link_optical"/>
  </joint>

  <!--Joint Hokuyo-->

  <joint type="fixed" name="hokuyo_joint">
    <origin xyz="0.17 0 0.08" rpy="0 0 0"/>
    <child link="hokuyo"/>
    <parent link="chassis"/>
    <axis xyz="0 1 0" rpy="0 0 0"/>
  </joint>

  <!--Materials-->

  <gazebo reference="left_wheel">
    <material>Gazebo/Green</material>
  </gazebo>

  <gazebo reference="right_wheel">
    <material>Gazebo/Green</material>
  </gazebo>

  <gazebo reference="camera">
    <material>Gazebo/Gray</material>
  </gazebo>

  <gazebo reference="chassis">
    <material>Gazebo/Blue</material>
  </gazebo>

  <gazebo reference="body">
    <material>Gazebo/Orange</material>
  </gazebo>

</robot>
